Invalid HTTP request received.
Traceback (most recent call last):
  File "C:\Users\flori\AppData\Local\Programs\Python\Python39\lib\site-packages\uvicorn\protocols\http\h11_impl.py", line 136, in handle_events
    event = self.conn.next_event()
  File "C:\Users\flori\AppData\Local\Programs\Python\Python39\lib\site-packages\h11\_connection.py", line 443, in next_event
    exc._reraise_as_remote_protocol_error()
  File "C:\Users\flori\AppData\Local\Programs\Python\Python39\lib\site-packages\h11\_util.py", line 76, in _reraise_as_remote_protocol_error
    raise self
  File "C:\Users\flori\AppData\Local\Programs\Python\Python39\lib\site-packages\h11\_connection.py", line 425, in next_event
    event = self._extract_next_receive_event()
  File "C:\Users\flori\AppData\Local\Programs\Python\Python39\lib\site-packages\h11\_connection.py", line 367, in _extract_next_receive_event
    event = self._reader(self._receive_buffer)
  File "C:\Users\flori\AppData\Local\Programs\Python\Python39\lib\site-packages\h11\_readers.py", line 68, in maybe_read_from_IDLE_client
    raise LocalProtocolError("illegal request line")
h11._util.RemoteProtocolError: illegal request line
Invalid HTTP request received.
Traceback (most recent call last):
  File "C:\Users\flori\AppData\Local\Programs\Python\Python39\lib\site-packages\uvicorn\protocols\http\h11_impl.py", line 136, in handle_events
    event = self.conn.next_event()
  File "C:\Users\flori\AppData\Local\Programs\Python\Python39\lib\site-packages\h11\_connection.py", line 443, in next_event
    exc._reraise_as_remote_protocol_error()
  File "C:\Users\flori\AppData\Local\Programs\Python\Python39\lib\site-packages\h11\_util.py", line 76, in _reraise_as_remote_protocol_error
    raise self
  File "C:\Users\flori\AppData\Local\Programs\Python\Python39\lib\site-packages\h11\_connection.py", line 425, in next_event
    event = self._extract_next_receive_event()
  File "C:\Users\flori\AppData\Local\Programs\Python\Python39\lib\site-packages\h11\_connection.py", line 367, in _extract_next_receive_event
    event = self._reader(self._receive_buffer)
  File "C:\Users\flori\AppData\Local\Programs\Python\Python39\lib\site-packages\h11\_readers.py", line 72, in maybe_read_from_IDLE_client
    matches = validate(
  File "C:\Users\flori\AppData\Local\Programs\Python\Python39\lib\site-packages\h11\_util.py", line 88, in validate
    raise LocalProtocolError(msg)
h11._util.RemoteProtocolError: illegal request line: bytearray(b'\x16\x03\x01\x02\x00\x01\x00\x01\xfc\x03\x03\xf5A\xfd\xd79\xe5:_\xf7\xb4k~8J]x=\x16\x8bg$\xef\xbe\x99o\xe7\xd1\xa9\x98\xb0v\x0b *&&\x96\xf2\xf1#^\x1b\x07\x173\x9c\x00#\x0fL\x84B\xdc\xc5\x89\x80\x1c\x94R_b\x0f\x97\x02\xde\x00 ')
Invalid HTTP request received.
Traceback (most recent call last):
  File "C:\Users\flori\AppData\Local\Programs\Python\Python39\lib\site-packages\uvicorn\protocols\http\h11_impl.py", line 136, in handle_events
    event = self.conn.next_event()
  File "C:\Users\flori\AppData\Local\Programs\Python\Python39\lib\site-packages\h11\_connection.py", line 443, in next_event
    exc._reraise_as_remote_protocol_error()
  File "C:\Users\flori\AppData\Local\Programs\Python\Python39\lib\site-packages\h11\_util.py", line 76, in _reraise_as_remote_protocol_error
    raise self
  File "C:\Users\flori\AppData\Local\Programs\Python\Python39\lib\site-packages\h11\_connection.py", line 425, in next_event
    event = self._extract_next_receive_event()
  File "C:\Users\flori\AppData\Local\Programs\Python\Python39\lib\site-packages\h11\_connection.py", line 367, in _extract_next_receive_event
    event = self._reader(self._receive_buffer)
  File "C:\Users\flori\AppData\Local\Programs\Python\Python39\lib\site-packages\h11\_readers.py", line 68, in maybe_read_from_IDLE_client
    raise LocalProtocolError("illegal request line")
h11._util.RemoteProtocolError: illegal request line
Invalid HTTP request received.
Traceback (most recent call last):
  File "C:\Users\flori\AppData\Local\Programs\Python\Python39\lib\site-packages\uvicorn\protocols\http\h11_impl.py", line 136, in handle_events
    event = self.conn.next_event()
  File "C:\Users\flori\AppData\Local\Programs\Python\Python39\lib\site-packages\h11\_connection.py", line 443, in next_event
    exc._reraise_as_remote_protocol_error()
  File "C:\Users\flori\AppData\Local\Programs\Python\Python39\lib\site-packages\h11\_util.py", line 76, in _reraise_as_remote_protocol_error
    raise self
  File "C:\Users\flori\AppData\Local\Programs\Python\Python39\lib\site-packages\h11\_connection.py", line 425, in next_event
    event = self._extract_next_receive_event()
  File "C:\Users\flori\AppData\Local\Programs\Python\Python39\lib\site-packages\h11\_connection.py", line 367, in _extract_next_receive_event
    event = self._reader(self._receive_buffer)
  File "C:\Users\flori\AppData\Local\Programs\Python\Python39\lib\site-packages\h11\_readers.py", line 68, in maybe_read_from_IDLE_client
    raise LocalProtocolError("illegal request line")
h11._util.RemoteProtocolError: illegal request line
Invalid HTTP request received.
Traceback (most recent call last):
  File "C:\Users\flori\AppData\Local\Programs\Python\Python39\lib\site-packages\uvicorn\protocols\http\h11_impl.py", line 136, in handle_events
    event = self.conn.next_event()
  File "C:\Users\flori\AppData\Local\Programs\Python\Python39\lib\site-packages\h11\_connection.py", line 443, in next_event
    exc._reraise_as_remote_protocol_error()
  File "C:\Users\flori\AppData\Local\Programs\Python\Python39\lib\site-packages\h11\_util.py", line 76, in _reraise_as_remote_protocol_error
    raise self
  File "C:\Users\flori\AppData\Local\Programs\Python\Python39\lib\site-packages\h11\_connection.py", line 425, in next_event
    event = self._extract_next_receive_event()
  File "C:\Users\flori\AppData\Local\Programs\Python\Python39\lib\site-packages\h11\_connection.py", line 367, in _extract_next_receive_event
    event = self._reader(self._receive_buffer)
  File "C:\Users\flori\AppData\Local\Programs\Python\Python39\lib\site-packages\h11\_readers.py", line 72, in maybe_read_from_IDLE_client
    matches = validate(
  File "C:\Users\flori\AppData\Local\Programs\Python\Python39\lib\site-packages\h11\_util.py", line 88, in validate
    raise LocalProtocolError(msg)
h11._util.RemoteProtocolError: illegal request line: bytearray(b'\x16\x03\x01\x02\x00\x01\x00\x01\xfc\x03\x03\xe4e\x14\xa0\xffTC\xc9\x05\xc0\xae\xced\xdd\xf5>\xc2\x8eB\xb3\x9f\x01\xc7\x84\xd7i\xa0M\x87\x91\x8a\x99 \x11\xe5\xfa\x82\x0fm\x8e[t\xe8w/\x00p\xcd\x86\x82\xad*\x1fY\xe5I\x04/\xc8G\xf54\x0f\xdd\xde\x00 ')
Shutting down
Waiting for application shutdown.
Application shutdown complete.
Finished server process [19704]
Started server process [10416]
Waiting for application startup.
Application startup complete.
Uvicorn running on http://192.168.178.44:8000 (Press CTRL+C to quit)
Shutting down
Waiting for application shutdown.
Application shutdown complete.
Finished server process [10416]
Started server process [15796]
Waiting for application startup.
Application startup complete.
Uvicorn running on http://192.168.178.44:8000 (Press CTRL+C to quit)
Started server process [5036]
Waiting for application startup.
Application startup complete.
Uvicorn running on http://192.168.178.44:8000 (Press CTRL+C to quit)
Shutting down
Waiting for connections to close. (CTRL+C to force quit)
Finished server process [5036]
2022-01-22 14:57:25,722 - uvicorn.error - ERROR: Traceback (most recent call last):
  File "C:\Users\flori\AppData\Local\Programs\Python\Python39\lib\site-packages\starlette\routing.py", line 624, in lifespan
    await receive()
  File "C:\Users\flori\AppData\Local\Programs\Python\Python39\lib\site-packages\uvicorn\lifespan\on.py", line 135, in receive
    return await self.receive_queue.get()
  File "C:\Users\flori\AppData\Local\Programs\Python\Python39\lib\asyncio\queues.py", line 166, in get
    await getter
asyncio.exceptions.CancelledError

Traceback (most recent call last):
  File "C:\Users\flori\AppData\Local\Programs\Python\Python39\lib\site-packages\starlette\routing.py", line 624, in lifespan
    await receive()
  File "C:\Users\flori\AppData\Local\Programs\Python\Python39\lib\site-packages\uvicorn\lifespan\on.py", line 135, in receive
    return await self.receive_queue.get()
  File "C:\Users\flori\AppData\Local\Programs\Python\Python39\lib\asyncio\queues.py", line 166, in get
    await getter
asyncio.exceptions.CancelledError

2022-01-22 14:57:25,724 - asyncio - ERROR: Exception in callback handle_http.<locals>.retrieve_exception(<Task cancell...erver.py:104>>) at C:\Users\flori\AppData\Local\Programs\Python\Python39\lib\site-packages\uvicorn\_handlers\http.py:56
handle: <Handle handle_http.<locals>.retrieve_exception(<Task cancell...erver.py:104>>) at C:\Users\flori\AppData\Local\Programs\Python\Python39\lib\site-packages\uvicorn\_handlers\http.py:56>
Traceback (most recent call last):
  File "C:\Users\flori\AppData\Local\Programs\Python\Python39\lib\site-packages\uvicorn\server.py", line 107, in handler
    await handle_http(
  File "C:\Users\flori\AppData\Local\Programs\Python\Python39\lib\site-packages\uvicorn\_handlers\http.py", line 87, in handle_http
    await connection_lost
asyncio.exceptions.CancelledError

During handling of the above exception, another exception occurred:

Traceback (most recent call last):
  File "C:\Users\flori\AppData\Local\Programs\Python\Python39\lib\asyncio\events.py", line 80, in _run
    self._context.run(self._callback, *self._args)
  File "C:\Users\flori\AppData\Local\Programs\Python\Python39\lib\site-packages\uvicorn\_handlers\http.py", line 58, in retrieve_exception
    exc = task.exception()
asyncio.exceptions.CancelledError
2022-01-22 14:57:25,998 - asyncio - ERROR: Exception in callback handle_http.<locals>.retrieve_exception(<Task cancell...erver.py:104>>) at C:\Users\flori\AppData\Local\Programs\Python\Python39\lib\site-packages\uvicorn\_handlers\http.py:56
handle: <Handle handle_http.<locals>.retrieve_exception(<Task cancell...erver.py:104>>) at C:\Users\flori\AppData\Local\Programs\Python\Python39\lib\site-packages\uvicorn\_handlers\http.py:56>
Traceback (most recent call last):
  File "C:\Users\flori\AppData\Local\Programs\Python\Python39\lib\site-packages\uvicorn\server.py", line 107, in handler
    await handle_http(
  File "C:\Users\flori\AppData\Local\Programs\Python\Python39\lib\site-packages\uvicorn\_handlers\http.py", line 87, in handle_http
    await connection_lost
asyncio.exceptions.CancelledError

During handling of the above exception, another exception occurred:

Traceback (most recent call last):
  File "C:\Users\flori\AppData\Local\Programs\Python\Python39\lib\asyncio\events.py", line 80, in _run
    self._context.run(self._callback, *self._args)
  File "C:\Users\flori\AppData\Local\Programs\Python\Python39\lib\site-packages\uvicorn\_handlers\http.py", line 58, in retrieve_exception
    exc = task.exception()
asyncio.exceptions.CancelledError
